Workbook

Sheet README
A1: Stimulus Expansion — Sign-off Workbook (NIL-53 / F1)
A2: Generated 2026-07-01 by Fable 5. Every gloss and pair is a PROPOSAL requiring human sign-off (Nils). Invariant 4: core-task pairs are real contrastive same-modality ideophones.
A4: Provenance: NINJAL LWP for BCCWJ top-600 (frequency, script share) + Iida & Akita 2023 perceptual strength norms (modality, strength, iconicity). Join key: Hepburn romaji; final sokuon = "q".
A5: Pools: A = in both top600 and norms (full covariates). B = norms only (script frequency needs SketchEngine/jpTenTen lookup).
A6: Scoring: 0.40·z(max perceptual strength) + 0.30·z(log10 freq) + 0.20·modality-scarcity (aud 1.0 > haptic 0.8 > int 0.4 > vis 0.2 > gust 0.1, ×2) + 0.10·pool-A completeness.
A8: Pairs proposed | B8: =COUNTA(Pairs!A2:A100) -> 23
A9: — both words new | B9: =COUNTIF(Pairs!E2:E100,FALSE()) -> 13
A10: — mixed (reuses an existing thesis word) | B10: =COUNTIF(Pairs!E2:E100,TRUE()) -> 10
A11: New recordings needed (audio gate — separate decision) | B11: =SUM(Pairs!H2:H100) -> 36
A12: Pairs signed off | B12: =COUNTIF(Pairs!I2:I100,"yes") -> 0
A14: Sign-off protocol: for each pair set sign_off = yes / no / revise. For mixed pairs ALSO confirm thesis_modality_check (the existing word's thesis modality must match the pair's floor — haptic floor reuses re-classify thesis words per norms).
A15: Gloss style follows the thesis meaning-prompt convention: short English phrase, lowercase, comma-separated senses.

Sheet Candidates
A1: key | B1: pool | C1: hira | D1: kata | E1: Dominant_modality | F1: Maximum_perceptual_strength | G1: Iconicity | H1: Modality_exclusivity | I1: freq_uni | J1: kata_share | K1: redup | L1: voiced_onset | M1: ri_suffix | N1: final_q | O1: len_morae_approx | P1: score | Q1: draft_gloss | R1: sign_off | S1: notes
A2: shittori | B2: A | C2: しっとり | D2: シットリ | E2: Haptic | F2: 4.636 | H2: 20.556 | I2: 622 | J2: 0.024 | K2: =FALSE() -> FALSE | L2: =FALSE() -> FALSE | M2: =TRUE() -> TRUE | N2: =FALSE() -> FALSE | O2: 3 | P2: 1.248 | Q2: moist, silky-damp
A3: butsubutsu | B3: A | C3: ぶつぶつ | D3: ブツブツ | E3: Haptic | F3: 4.636 | G3: 3.2 | H3: 25 | I3: 494 | J3: 0.537 | K3: =TRUE() -> TRUE | L3: =TRUE() -> TRUE | M3: =FALSE() -> FALSE | N3: =FALSE() -> FALSE | O3: 4 | P3: 1.216 | Q3: bumpy, covered in small lumps
A4: saq | B4: B | E4: Auditory | F4: 4.3 | H4: 25.157 | I4: 1687 | K4: =FALSE() -> FALSE | L4: =FALSE() -> FALSE | M4: =FALSE() -> FALSE | N4: =TRUE() -> TRUE | O4: 2 | P4: 1.178 | Q4: swiftly, in one stroke
A5: nikkori | B5: A | C5: にっこり | D5: ニッコリ | E5: Visual | F5: 4.8 | H5: 58.537 | I5: 825 | J5: 0.223 | K5: =FALSE() -> FALSE | L5: =FALSE() -> FALSE | M5: =TRUE() -> TRUE | N5: =FALSE() -> FALSE | O5: 4 | P5: 1.142 | Q5: beaming, with a broad smile
A6: gyuq | B6: B | E6: Haptic | F6: 4.636 | H6: 27.545 | I6: 482 | K6: =FALSE() -> FALSE | L6: =TRUE() -> TRUE | M6: =FALSE() -> FALSE | N6: =TRUE() -> TRUE | O6: 2 | P6: 1.112 | Q6: squeezing tight
A7: batabata | B7: A | C7: ばたばた | D7: バタバタ | E7: Auditory | F7: 4.2 | H7: 23.27 | I7: 544 | J7: 0.776 | K7: =TRUE() -> TRUE | L7: =TRUE() -> TRUE | M7: =FALSE() -> FALSE | N7: =FALSE() -> FALSE | O7: 4 | P7: 1.06 | Q7: clattering, flapping about
A8: fuwafuwa | B8: A | C8: ふわふわ | D8: フワフワ | E8: Haptic | F8: 4.2 | H8: 24.638 | I8: 473 | J8: 0.224 | K8: =TRUE() -> TRUE | L8: =FALSE() -> FALSE | M8: =FALSE() -> FALSE | N8: =FALSE() -> FALSE | O8: 4 | P8: 0.96 | Q8: soft, fluffy, airy
A9: jikkuri | B9: A | C9: じっくり | D9: ジックリ | E9: Visual | F9: 4.3 | H9: 15.429 | I9: 1471 | J9: 0.019 | K9: =FALSE() -> FALSE | L9: =TRUE() -> TRUE | M9: =TRUE() -> TRUE | N9: =FALSE() -> FALSE | O9: 3 | P9: 0.939 | Q9: carefully, taking a long look
A10: shikkari | B10: B | E10: Visual | F10: 4 | H10: 7.732 | I10: 7921 | K10: =FALSE() -> FALSE | L10: =FALSE() -> FALSE | M10: =TRUE() -> TRUE | N10: =FALSE() -> FALSE | O10: 3 | P10: 0.908 | Q10: firmly, reliably
A11: sarasara | B11: A | C11: さらさら | D11: サラサラ | E11: Haptic | F11: 4.077 | H11: 25.568 | I11: 459 | J11: 0.515 | K11: =TRUE() -> TRUE | L11: =FALSE() -> FALSE | M11: =FALSE() -> FALSE | N11: =FALSE() -> FALSE | O11: 4 | P11: 0.885 | Q11: smooth, dry, silky
A12: chiraq | B12: B | E12: Visual | F12: 4.4 | H12: 62.857 | I12: 864 | K12: =FALSE() -> FALSE | L12: =FALSE() -> FALSE | M12: =FALSE() -> FALSE | N12: =TRUE() -> TRUE | O12: 3 | P12: 0.82 | Q12: catching sight for an instant
A13: guruguru | B13: A | C13: ぐるぐる | D13: グルグル | E13: Interoceptive | F13: 4.083 | H13: 29.53 | I13: 728 | J13: 0.302 | K13: =TRUE() -> TRUE | L13: =TRUE() -> TRUE | M13: =FALSE() -> FALSE | N13: =FALSE() -> FALSE | O13: 4 | P13: 0.795 | Q13: head spinning, dizzy whirl
A14: pittari | B14: A | C14: ぴったり | D14: ピッタリ | E14: Haptic | F14: 3.5 | H14: 25.893 | I14: 2099 | J14: 0.377 | K14: =FALSE() -> FALSE | L14: =FALSE() -> FALSE | M14: =TRUE() -> TRUE | N14: =FALSE() -> FALSE | O14: 3 | P14: 0.772 | Q14: fitting exactly, snug
A15: gakkari | B15: A | C15: がっかり | D15: ガッカリ | E15: Visual | F15: 4.1 | H15: 16.667 | I15: 907 | J15: 0.352 | K15: =FALSE() -> FALSE | L15: =TRUE() -> TRUE | M15: =TRUE() -> TRUE | N15: =FALSE() -> FALSE | O15: 3 | P15: 0.756 | Q15: crestfallen, deflated
A16: mechakucha | B16: A | C16: めちゃくちゃ | D16: メチャクチャ | E16: Visual | F16: 4.182 | H16: 16.86 | I16: 591 | J16: 0.153 | K16: =FALSE() -> FALSE | L16: =FALSE() -> FALSE | M16: =FALSE() -> FALSE | N16: =FALSE() -> FALSE | O16: 4 | P16: 0.741 | Q16: in total disarray
A17: assari | B17: A | C17: あっさり | D17: アッサリ | E17: Gustatory | F17: 4 | H17: 23.664 | I17: 1446 | J17: 0.066 | K17: =FALSE() -> FALSE | L17: =FALSE() -> FALSE | M17: =TRUE() -> TRUE | N17: =FALSE() -> FALSE | O17: 3 | P17: 0.725 | Q17: light, plain (taste)
A18: potsun | B18: A | C18: ぽつん | D18: ポツン | E18: Visual | F18: 4.3 | G18: 4.077 | H18: 27.397 | I18: 307 | J18: 0.479 | K18: =FALSE() -> FALSE | L18: =FALSE() -> FALSE | M18: =FALSE() -> FALSE | N18: =FALSE() -> FALSE | O18: 3 | P18: 0.715 | Q18: all alone, a solitary dot
A19: dorodoro | B19: A | C19: どろどろ | D19: ドロドロ | E19: Haptic | F19: 3.9 | G19: 3.429 | H19: 20.29 | I19: 280 | J19: 0.727 | K19: =TRUE() -> TRUE | L19: =TRUE() -> TRUE | M19: =FALSE() -> FALSE | N19: =FALSE() -> FALSE | O19: 4 | P19: 0.714 | Q19: thick, muddy, syrupy
A20: togetoge | B20: B | E20: Haptic | F20: 4.636 | G20: 3.455 | H20: 29.605 | I20: 25 | K20: =TRUE() -> TRUE | L20: =FALSE() -> FALSE | M20: =FALSE() -> FALSE | N20: =FALSE() -> FALSE | O20: 4 | P20: 0.69 | Q20: prickly, thorny
A21: nebaneba | B21: A | C21: ねばねば | D21: ネバネバ | E21: Haptic | F21: 4.077 | G21: 3.733 | H21: 17.703 | I21: 102 | J21: 0.695 | K21: =TRUE() -> TRUE | L21: =FALSE() -> FALSE | M21: =FALSE() -> FALSE | N21: =FALSE() -> FALSE | O21: 6 | P21: 0.671 | Q21: sticky, gooey
A22: fusafusa | B22: A | C22: ふさふさ | D22: フサフサ | E22: Haptic | F22: 4.091 | G22: 3.417 | H22: 29.71 | I22: 92 | J22: 0.455 | K22: =TRUE() -> TRUE | L22: =FALSE() -> FALSE | M22: =FALSE() -> FALSE | N22: =FALSE() -> FALSE | O22: 4 | P22: 0.664 | Q22: fluffy, tufted
A23: chirari | B23: A | C23: ちらり | D23: チラリ | E23: Visual | F23: 4 | H23: 52.778 | I23: 649 | J23: 0.352 | K23: =FALSE() -> FALSE | L23: =FALSE() -> FALSE | M23: =TRUE() -> TRUE | N23: =FALSE() -> FALSE | O23: 3 | P23: 0.651 | Q23: a fleeting glimpse
A24: kachakacha | B24: B | E24: Auditory | F24: 4.2 | G24: 3.333 | H24: 40.385 | I24: 40 | K24: =TRUE() -> TRUE | L24: =FALSE() -> FALSE | M24: =FALSE() -> FALSE | N24: =FALSE() -> FALSE | O24: 4 | P24: 0.588 | Q24: clattering of small hard objects
A25: suq | B25: B | E25: Auditory | F25: 3.5 | H25: 14.103 | I25: 638 | K25: =FALSE() -> FALSE | L25: =FALSE() -> FALSE | M25: =FALSE() -> FALSE | N25: =TRUE() -> TRUE | O25: 2 | P25: 0.582 | Q25: smoothly, without resistance
A26: yukkuri | B26: B | E26: Visual | F26: 3.4 | H26: 27.523 | I26: 8725 | K26: =FALSE() -> FALSE | L26: =FALSE() -> FALSE | M26: =TRUE() -> TRUE | N26: =FALSE() -> FALSE | O26: 3 | P26: 0.578 | Q26: slowly, unhurriedly
A27: urouro | B27: A | C27: うろうろ | D27: ウロウロ | E27: Visual | F27: 3.9 | H27: 34.821 | I27: 565 | J27: 0.474 | K27: =TRUE() -> TRUE | L27: =FALSE() -> FALSE | M27: =FALSE() -> FALSE | N27: =FALSE() -> FALSE | O27: 4 | P27: 0.574 | Q27: wandering aimlessly
A28: pokipoki | B28: B | E28: Auditory | F28: 4.3 | G28: 2.905 | H28: 26.25 | I28: 24 | K28: =TRUE() -> TRUE | L28: =FALSE() -> FALSE | M28: =FALSE() -> FALSE | N28: =FALSE() -> FALSE | O28: 4 | P28: 0.572 | Q28: snapping dry sticks
A29: tappuri | B29: A | C29: たっぷり | D29: タップリ | E29: Visual | F29: 3.5 | H29: 18.11 | I29: 2652 | J29: 0.045 | K29: =FALSE() -> FALSE | L29: =FALSE() -> FALSE | M29: =TRUE() -> TRUE | N29: =FALSE() -> FALSE | O29: 3 | P29: 0.566 | Q29: amply, in generous measure
A30: kishikishi | B30: B | E30: Auditory | F30: 4.4 | G30: 2.385 | H30: 27.215 | I30: 13 | K30: =TRUE() -> TRUE | L30: =FALSE() -> FALSE | M30: =FALSE() -> FALSE | N30: =FALSE() -> FALSE | O30: 4 | P30: 0.542 | Q30: creaking under strain
A31: uttori | B31: A | C31: うっとり | D31: ウットリ | E31: Interoceptive | F31: 3.692 | H31: 11.538 | I31: 471 | J31: 0.131 | K31: =FALSE() -> FALSE | L31: =FALSE() -> FALSE | M31: =TRUE() -> TRUE | N31: =FALSE() -> FALSE | O31: 3 | P31: 0.509 | Q31: spellbound, dreamily entranced
A32: kurukuru | B32: A | C32: くるくる | D32: クルクル | E32: Visual | F32: 3.8 | H32: 33.636 | I32: 527 | J32: 0.336 | K32: =TRUE() -> TRUE | L32: =FALSE() -> FALSE | M32: =FALSE() -> FALSE | N32: =FALSE() -> FALSE | O32: 4 | P32: 0.507 | Q32: twirling round and round
A33: daradara | B33: A | C33: だらだら | D33: ダラダラ | E33: Interoceptive | F33: 3.636 | H33: 22 | I33: 497 | J33: 0.519 | K33: =TRUE() -> TRUE | L33: =TRUE() -> TRUE | M33: =FALSE() -> FALSE | N33: =FALSE() -> FALSE | O33: 4 | P33: 0.485 | Q33: listless, dragging on
A34: kutsukutsu | B34: B | E34: Auditory | F34: 4.1 | G34: 1.818 | H34: 23.239 | I34: 27 | K34: =TRUE() -> TRUE | L34: =FALSE() -> FALSE | M34: =FALSE() -> FALSE | N34: =FALSE() -> FALSE | O34: 4 | P34: 0.474 | Q34: chuckling under one's breath
A35: gakun | B35: A | C35: がくん | D35: ガクン | E35: Interoceptive | F35: 4.083 | G35: 1.929 | H35: 32.639 | I35: 68 | J35: 0.666 | K35: =FALSE() -> FALSE | L35: =TRUE() -> TRUE | M35: =FALSE() -> FALSE | N35: =FALSE() -> FALSE | O35: 3 | P35: 0.457 | Q35: a sudden jolt or drop
A36: batchiri | B36: B | E36: Visual | F36: 3.818 | H36: 24.265 | I36: 498 | K36: =FALSE() -> FALSE | L36: =TRUE() -> TRUE | M36: =TRUE() -> TRUE | N36: =FALSE() -> FALSE | O36: 3 | P36: 0.409 | Q36: perfectly, without a hitch
A37: furafura | B37: A | C37: ふらふら | D37: フラフラ | E37: Interoceptive | F37: 3.455 | H37: 39.583 | I37: 564 | J37: 0.492 | K37: =TRUE() -> TRUE | L37: =FALSE() -> FALSE | M37: =FALSE() -> FALSE | N37: =FALSE() -> FALSE | O37: 4 | P37: 0.399 | Q37: unsteady, wobbly
A38: pikari | B38: B | E38: Visual | F38: 4.727 | G38: 1.091 | H38: 47.619 | I38: 12 | K38: =FALSE() -> FALSE | L38: =FALSE() -> FALSE | M38: =TRUE() -> TRUE | N38: =FALSE() -> FALSE | O38: 3 | P38: 0.397 | Q38: a sudden flash of light
A39: hakkiri | B39: B | E39: Interoceptive | F39: 2.9 | H39: 15.652 | I39: 9870 | K39: =FALSE() -> FALSE | L39: =FALSE() -> FALSE | M39: =TRUE() -> TRUE | N39: =FALSE() -> FALSE | O39: 3 | P39: 0.39 | Q39: clearly, distinctly
A40: tsururi | B40: B | E40: Haptic | F40: 3.909 | G40: 3.8 | H40: 22.892 | I40: 47 | K40: =FALSE() -> FALSE | L40: =FALSE() -> FALSE | M40: =TRUE() -> TRUE | N40: =FALSE() -> FALSE | O40: 3 | P40: 0.364 | Q40: slipping smoothly
...

Sheet Pairs
A1: pair_id | B1: floor | C1: word_1 (new) | D1: word_2 | E1: word_2_is_existing_thesis_word | F1: contrast_axis | G1: difficulty_prior | H1: new_recordings | I1: sign_off | J1: thesis_modality_check | K1: notes
A2: A1 | B2: Auditory | C2: batabata | D2: hissori | E2: =FALSE() -> FALSE | F2: loud commotion vs silence (antonymic) | G2: easy | H2: 2 | K2: w1: clattering, flapping about | w2: hushed, still
A3: A2 | B3: Auditory | C3: boribori | D3: poripori | E3: =TRUE() -> TRUE | F3: loud vs quiet crunch — minimal contrast | G3: hard | H3: 1 | J3: CHECK | K3: w1: crunching loudly | w2: nibbling with a quiet crunch
A4: A3 | B4: Auditory | C4: potopoto | D4: jaajaa | E4: =TRUE() -> TRUE | F4: dripping vs gushing water | G4: easy | H4: 1 | J4: CHECK | K4: w1: dripping in steady drops | w2: gushing noisily
A5: A4 | B5: Auditory | C5: kerakera | D5: kutsukutsu | E5: =FALSE() -> FALSE | F5: open vs suppressed laughter | G5: medium | H5: 2 | K5: w1: cackling openly | w2: chuckling under one's breath
A6: A5 | B6: Auditory | C6: pokipoki | D6: chokichoki | E6: =FALSE() -> FALSE | F6: snapping vs snipping | G6: medium | H6: 2 | K6: w1: snapping dry sticks | w2: snipping with scissors
A7: A6 | B7: Auditory | C7: kishikishi | D7: dotadota | E7: =FALSE() -> FALSE | F7: creaking vs stomping | G7: medium | H7: 2 | K7: w1: creaking under strain | w2: stomping heavily
A8: H1 | B8: Haptic | C8: sarasara | D8: nebaneba | E8: =FALSE() -> FALSE | F8: dry-smooth vs sticky (textbook contrast) | G8: easy | H8: 2 | K8: w1: smooth, dry, silky | w2: sticky, gooey
A9: H2 | B9: Haptic | C9: fuwafuwa | D9: gotsugotsu | E9: =TRUE() -> TRUE | F9: fluffy-soft vs rugged-hard | G9: easy | H9: 1 | J9: CHECK | K9: w1: soft, fluffy, airy | w2: rugged, craggy
A10: H3 | B10: Haptic | C10: shittori | D10: bosabosa | E10: =TRUE() -> TRUE | F10: silky-moist vs dry-tousled | G10: medium | H10: 1 | J10: CHECK | K10: w1: moist, silky-damp | w2: dry, tousled
A11: H4 | B11: Haptic | C11: dorodoro | D11: tsururi | E11: =FALSE() -> FALSE | F11: viscous sludge vs frictionless slip | G11: medium | H11: 2 | K11: w1: thick, muddy, syrupy | w2: slipping smoothly
A12: H5 | B12: Haptic | C12: togetoge | D12: fusafusa | E12: =FALSE() -> FALSE | F12: prickly vs fluffy | G12: easy | H12: 2 | K12: w1: prickly, thorny | w2: fluffy, tufted
A13: H6 | B13: Haptic | C13: gyuq | D13: funyafunya | E13: =FALSE() -> FALSE | F13: tight grip vs limp squish | G13: medium | H13: 2 | K13: w1: squeezing tight | w2: limp, squishy
A14: I1 | B14: Interoceptive | C14: uttori | D14: unzari | E14: =TRUE() -> TRUE | F14: entranced vs fed up | G14: easy | H14: 1 | J14: CHECK | K14: w1: spellbound, dreamily entranced | w2: fed up, sick of it
A15: I2 | B15: Interoceptive | C15: hiyari | D15: hokkori | E15: =TRUE() -> TRUE | F15: chill of fear vs cozy warmth | G15: easy | H15: 1 | J15: CHECK | K15: w1: a chill of sudden fear | w2: warm and comforted
A16: I3 | B16: Interoceptive | C16: daradara | D16: kippari | E16: =FALSE() -> FALSE | F16: listless vs decisive | G16: medium | H16: 2 | K16: w1: listless, dragging on | w2: decisive, clean-cut
A17: I4 | B17: Interoceptive | C17: guruguru | D17: gakun | E17: =FALSE() -> FALSE | F17: dizzy whirl vs sudden jolt | G17: medium | H17: 2 | K17: w1: head spinning, dizzy whirl | w2: a sudden jolt or drop
A18: I5 | B18: Interoceptive | C18: pokan | D18: wakuwaku | E18: =TRUE() -> TRUE | F18: blank daze vs tingling excitement | G18: medium | H18: 1 | J18: CHECK | K18: w1: blank, vacantly dazed | w2: tingling with excitement
A19: V1 | B19: Visual | C19: chirari | D19: jikkuri | E19: =FALSE() -> FALSE | F19: fleeting glimpse vs long careful look | G19: medium | H19: 2 | K19: w1: a fleeting glimpse | w2: carefully, taking a long look
A20: V2 | B20: Visual | C20: potsun | D20: bisshiri | E20: =TRUE() -> TRUE | F20: isolated dot vs densely packed | G20: easy | H20: 1 | J20: CHECK | K20: w1: all alone, a solitary dot | w2: packed densely
A21: V3 | B21: Visual | C21: kurukuru | D21: pitari | E21: =TRUE() -> TRUE | F21: twirling vs stopping exactly | G21: medium | H21: 1 | J21: CHECK | K21: w1: twirling round and round | w2: stopping exactly, fitting perfectly
A22: V4 | B22: Visual | C22: urouro | D22: sassa | E22: =FALSE() -> FALSE | F22: aimless wandering vs brisk purpose | G22: medium | H22: 2 | K22: w1: wandering aimlessly | w2: briskly, without dawdling
A23: V5 | B23: Visual | C23: pikari | D23: donyori | E23: =TRUE() -> TRUE | F23: flash of light vs leaden dullness | G23: easy | H23: 1 | J23: CHECK | K23: w1: a sudden flash of light | w2: dull, leaden, overcast
A24: V6 | B24: Visual | C24: mechakucha | D24: kitchiri | E24: =FALSE() -> FALSE | F24: total disarray vs neat precision | G24: easy | H24: 2 | K24: w1: in total disarray | w2: neatly, precisely

Sheet ConventionFrontier
A1: key | B1: freq_uni | C1: draft_gloss | D1: why here
A2: hakkiri | B2: 9870 | C2: clearly, distinctly | D2: fully conventionalized ideophone — iconicity opaque; fuel for a "convention takes over" hard tier / Lexicalization Frontier idea (F2), not core pairs
A3: yukkuri | B3: 8725 | C3: slowly, unhurriedly | D3: fully conventionalized ideophone — iconicity opaque; fuel for a "convention takes over" hard tier / Lexicalization Frontier idea (F2), not core pairs
A4: shikkari | B4: 7921 | C4: firmly, reliably | D4: fully conventionalized ideophone — iconicity opaque; fuel for a "convention takes over" hard tier / Lexicalization Frontier idea (F2), not core pairs
A5: sukkari | B5: 1872 | C5: completely, utterly | D5: fully conventionalized ideophone — iconicity opaque; fuel for a "convention takes over" hard tier / Lexicalization Frontier idea (F2), not core pairs
A6: bikkuri | B6: 4402 | C6: startled, surprised | D6: fully conventionalized ideophone — iconicity opaque; fuel for a "convention takes over" hard tier / Lexicalization Frontier idea (F2), not core pairs
